Workbook
Name rounding_decimal_places: [2]About!$A$123

Sheet CBAM - Mechanism Rules
A1: Scenario Selection --> | B1: CBAM Module | C1: Steel | F1: 2020 | G1: 2021 | H1: 2022 | I1: 2023 | J1: 2024 | K1: 2025 | L1: 2026 | M1: 2027 | N1: 2028 | O1: 2029 | P1: 2030 | Q1: 2031 | R1: 2032 | S1: 2033 | T1: 2034 | U1: 2035 | V1: 2036 | W1: 2037 | X1: 2038 | Y1: 2039 | Z1: 2040 | AA1: 2041 | AB1: 2042 | AC1: 2043 | AD1: 2044 | AE1: 2045 | AF1: 2046 | AG1: 2047 | AH1: 2048 | AI1: 2049 | AJ1: 2050
F2: 1 | G2: 2 | H2: 3 | I2: 4 | J2: 5 | K2: 6 | L2: 7 | M2: 8 | N2: 9 | O2: 10 | P2: 11 | Q2: 12 | R2: 13 | S2: 14 | T2: 15 | U2: 16 | V2: 17 | W2: 18 | X2: 19 | Y2: 20 | Z2: 21 | AA2: 22 | AB2: 23 | AC2: 24 | AD2: 25 | AE2: 26 | AF2: 27 | AG2: 28 | AH2: 29 | AI2: 30 | AJ2: 31
A3: CBAM-Mechanism Rules | C3: Value Options | F3: 2020 | G3: 2021 | H3: 2022 | I3: 2023 | J3: 2024 | K3: 2025 | L3: 2026 | M3: 2027 | N3: 2028 | O3: 2029 | P3: 2030 | Q3: 2031 | R3: 2032 | S3: 2033 | T3: 2034 | U3: 2035 | V3: 2036 | W3: 2037 | X3: 2038 | Y3: 2039 | Z3: 2040 | AA3: 2041 | AB3: 2042 | AC3: 2043 | AD3: 2044 | AE3: 2045 | AF3: 2046 | AG3: 2047 | AH3: 2048 | AI3: 2049 | AJ3: 2050
B4: Carbon Market Free Allowance Exit Ratio | C4: Free Allowance Exit | F4: 0 | G4: 0 | H4: 0 | I4: 0 | J4: 0 | K4: 0 | L4: 0.025 | M4: 0.05 | N4: 0.1 | O4: 0.225 | P4: 0.485 | Q4: 0.55 | R4: 0.625 | S4: 0.8 | T4: 1 | U4: 1 | V4: 1 | W4: 1 | X4: 1 | Y4: 1 | Z4: 1 | AA4: 1 | AB4: 1 | AC4: 1 | AD4: 1 | AE4: 1 | AF4: 1 | AG4: 1 | AH4: 1 | AI4: 1 | AJ4: 1
C5: Custom | F5: 0 | G5: 0 | H5: 0 | I5: 0 | J5: 0 | K5: 0 | L5: 0 | M5: 0 | N5: 0 | O5: 0 | P5: 0 | Q5: 0 | R5: 0 | S5: 0 | T5: 0 | U5: 0 | V5: 0 | W5: 0 | X5: 0 | Y5: 0 | Z5: 0 | AA5: 0 | AB5: 0 | AC5: 0 | AD5: 0 | AE5: 0 | AF5: 0 | AG5: 0 | AH5: 0 | AI5: 0 | AJ5: 0
B9: EU imports of Chinese steel products: volume and product structure | F9: 2020 | G9: 2021 | H9: 2022 | I9: 2023 | J9: 2024 | K9: 2025 | L9: 2026 | M9: 2027 | N9: 2028 | O9: 2029 | P9: 2030 | Q9: 2031 | R9: 2032 | S9: 2033 | T9: 2034 | U9: 2035 | V9: 2036 | W9: 2037 | X9: 2038 | Y9: 2039 | Z9: 2040 | AA9: 2041 | AB9: 2042 | AC9: 2043 | AD9: 2044 | AE9: 2045 | AF9: 2046 | AG9: 2047 | AH9: 2048 | AI9: 2049 | AJ9: 2050
C10: Trade volume | D10: =[1]对照表!$B$2 -> Sintered ore | F10: ='[1]5.2 附表2000-2050EU27_Import_CHZ'!BU50 -> 0 | G10: ='[1]5.2 附表2000-2050EU27_Import_CHZ'!BV50 -> 0 | H10: ='[1]5.2 附表2000-2050EU27_Import_CHZ'!BW50 -> 0 | I10: ='[1]5.2 附表2000-2050EU27_Import_CHZ'!BX50 -> 0 | J10: ='[1]5.2 附表2000-2050EU27_Import_CHZ'!BY50 -> 0 | K10: ='[1]5.2 附表2000-2050EU27_Import_CHZ'!BZ50 -> 0 | L10: ='[1]5.2 附表2000-2050EU27_Import_CHZ'!CA50 -> 0 | M10: ='[1]5.2 附表2000-2050EU27_Import_CHZ'!CB50 -> 0 | ... AJ10: ='[1]5.2 附表2000-2050EU27_Import_CHZ'!CY50 -> 0
C11: Trade volume | D11: =[1]对照表!$B$3 -> Alloys | F11: ='[1]5.2 附表2000-2050EU27_Import_CHZ'!BU51 -> 0.35 | G11: ='[1]5.2 附表2000-2050EU27_Import_CHZ'!BV51 -> 0.15 | H11: ='[1]5.2 附表2000-2050EU27_Import_CHZ'!BW51 -> 0.67 | I11: ='[1]5.2 附表2000-2050EU27_Import_CHZ'!BX51 -> 0.61 | J11: ='[1]5.2 附表2000-2050EU27_Import_CHZ'!BY51 -> 0.57 | K11: ='[1]5.2 附表2000-2050EU27_Import_CHZ'!BZ51 -> 0.52 | L11: ='[1]5.2 附表2000-2050EU27_Import_CHZ'!CA51 -> 0.48 | M11: ='[1]5.2 附表2000-2050EU27_Import_CHZ'!CB51 -> 0.44 | ... AJ11: ='[1]5.2 附表2000-2050EU27_Import_CHZ'!CY51 -> 0
B12: 0.5 | C12: Trade volume | D12: =[1]对照表!$B$4 -> Pig iron (BF) | F12: ='[1]5.2 附表2000-2050EU27_Import_CHZ'!BU$52*'CBAM - Mechanism Rules'!$B$12 -> 0 | G12: ='[1]5.2 附表2000-2050EU27_Import_CHZ'!BV$52*'CBAM - Mechanism Rules'!$B$12 -> 0.01 | H12: ='[1]5.2 附表2000-2050EU27_Import_CHZ'!BW$52*'CBAM - Mechanism Rules'!$B$12 -> 1.07 | I12: ='[1]5.2 附表2000-2050EU27_Import_CHZ'!BX$52*'CBAM - Mechanism Rules'!$B$12 -> 0.215 | J12: ='[1]5.2 附表2000-2050EU27_Import_CHZ'!BY$52*'CBAM - Mechanism Rules'!$B$12 -> 0.22 | K12: ='[1]5.2 附表2000-2050EU27_Import_CHZ'!BZ$52*'CBAM - Mechanism Rules'!$B$12 -> 0.22 | L12: ='[1]5.2 附表2000-2050EU27_Import_CHZ'!CA$52*'CBAM - Mechanism Rules'!$B$12 -> 0.225 | M12: ='[1]5.2 附表2000-2050EU27_Import_CHZ'!CB$52*'CBAM - Mechanism Rules'!$B$12 -> 0.225 | ... AJ12: ='[1]5.2 附表2000-2050EU27_Import_CHZ'!CY$52*'CBAM - Mechanism Rules'!$B$12 -> 0.26
B13: =1-B12 -> 0.5 | C13: Trade volume | D13: =[1]对照表!$B$5 -> Pig iron (smelting reduction) | F13: ='[1]5.2 附表2000-2050EU27_Import_CHZ'!BU$52*'CBAM - Mechanism Rules'!$B$13 -> 0 | G13: ='[1]5.2 附表2000-2050EU27_Import_CHZ'!BV$52*'CBAM - Mechanism Rules'!$B$13 -> 0.01 | H13: ='[1]5.2 附表2000-2050EU27_Import_CHZ'!BW$52*'CBAM - Mechanism Rules'!$B$13 -> 1.07 | I13: ='[1]5.2 附表2000-2050EU27_Import_CHZ'!BX$52*'CBAM - Mechanism Rules'!$B$13 -> 0.215 | J13: ='[1]5.2 附表2000-2050EU27_Import_CHZ'!BY$52*'CBAM - Mechanism Rules'!$B$13 -> 0.22 | K13: ='[1]5.2 附表2000-2050EU27_Import_CHZ'!BZ$52*'CBAM - Mechanism Rules'!$B$13 -> 0.22 | L13: ='[1]5.2 附表2000-2050EU27_Import_CHZ'!CA$52*'CBAM - Mechanism Rules'!$B$13 -> 0.225 | M13: ='[1]5.2 附表2000-2050EU27_Import_CHZ'!CB$52*'CBAM - Mechanism Rules'!$B$13 -> 0.225 | ... AJ13: ='[1]5.2 附表2000-2050EU27_Import_CHZ'!CY$52*'CBAM - Mechanism Rules'!$B$13 -> 0.26
C14: Trade volume | D14: =[1]对照表!$B$6 -> DRI | F14: ='[1]5.2 附表2000-2050EU27_Import_CHZ'!BU53 -> 0.01 | G14: ='[1]5.2 附表2000-2050EU27_Import_CHZ'!BV53 -> 0 | H14: ='[1]5.2 附表2000-2050EU27_Import_CHZ'!BW53 -> 0 | I14: ='[1]5.2 附表2000-2050EU27_Import_CHZ'!BX53 -> 0.01 | J14: ='[1]5.2 附表2000-2050EU27_Import_CHZ'!BY53 -> 0.01 | K14: ='[1]5.2 附表2000-2050EU27_Import_CHZ'!BZ53 -> 0.01 | L14: ='[1]5.2 附表2000-2050EU27_Import_CHZ'!CA53 -> 0.01 | M14: ='[1]5.2 附表2000-2050EU27_Import_CHZ'!CB53 -> 0.01 | ... AJ14: ='[1]5.2 附表2000-2050EU27_Import_CHZ'!CY53 -> 0.02
B15: 0.5 | C15: Trade volume | D15: =[1]对照表!$B$7 -> Crude steel (BOF route) | F15: ='[1]5.2 附表2000-2050EU27_Import_CHZ'!BU$54*'CBAM - Mechanism Rules'!$B15 -> 0.19 | G15: ='[1]5.2 附表2000-2050EU27_Import_CHZ'!BV$54*'CBAM - Mechanism Rules'!$B15 -> 0.17 | H15: ='[1]5.2 附表2000-2050EU27_Import_CHZ'!BW$54*'CBAM - Mechanism Rules'!$B15 -> 2.045 | I15: ='[1]5.2 附表2000-2050EU27_Import_CHZ'!BX$54*'CBAM - Mechanism Rules'!$B15 -> 0.535 | J15: ='[1]5.2 附表2000-2050EU27_Import_CHZ'!BY$54*'CBAM - Mechanism Rules'!$B15 -> 0.54 | K15: ='[1]5.2 附表2000-2050EU27_Import_CHZ'!BZ$54*'CBAM - Mechanism Rules'!$B15 -> 0.555 | L15: ='[1]5.2 附表2000-2050EU27_Import_CHZ'!CA$54*'CBAM - Mechanism Rules'!$B15 -> 0.565 | M15: ='[1]5.2 附表2000-2050EU27_Import_CHZ'!CB$54*'CBAM - Mechanism Rules'!$B15 -> 0.57 | ... AJ15: ='[1]5.2 附表2000-2050EU27_Import_CHZ'!CY$54*'CBAM - Mechanism Rules'!$B15 -> 0.705
B16: =1-B15 -> 0.5 | C16: Trade volume | D16: =[1]对照表!$B$8 -> Crude steel (EAF route) | F16: ='[1]5.2 附表2000-2050EU27_Import_CHZ'!BU$54*'CBAM - Mechanism Rules'!$B16 -> 0.19 | G16: ='[1]5.2 附表2000-2050EU27_Import_CHZ'!BV$54*'CBAM - Mechanism Rules'!$B16 -> 0.17 | H16: ='[1]5.2 附表2000-2050EU27_Import_CHZ'!BW$54*'CBAM - Mechanism Rules'!$B16 -> 2.045 | I16: ='[1]5.2 附表2000-2050EU27_Import_CHZ'!BX$54*'CBAM - Mechanism Rules'!$B16 -> 0.535 | J16: ='[1]5.2 附表2000-2050EU27_Import_CHZ'!BY$54*'CBAM - Mechanism Rules'!$B16 -> 0.54 | K16: ='[1]5.2 附表2000-2050EU27_Import_CHZ'!BZ$54*'CBAM - Mechanism Rules'!$B16 -> 0.555 | L16: ='[1]5.2 附表2000-2050EU27_Import_CHZ'!CA$54*'CBAM - Mechanism Rules'!$B16 -> 0.565 | M16: ='[1]5.2 附表2000-2050EU27_Import_CHZ'!CB$54*'CBAM - Mechanism Rules'!$B16 -> 0.57 | ... AJ16: ='[1]5.2 附表2000-2050EU27_Import_CHZ'!CY$54*'CBAM - Mechanism Rules'!$B16 -> 0.705
B17: =('[1]5.3.1 钢铁行业参数数据库'!F141+'[1]5.3.1 钢铁行业参数数据库'!F142)/'[1]5.3.1 钢铁行业参数数据库'!F146 -> 0.9 | C17: Trade volume | D17: =[1]对照表!$B$9 -> Steel (BF-BOF route) | F17: ='[1]5.2 附表2000-2050EU27_Import_CHZ'!BU$55*'CBAM - Mechanism Rules'!$B17 -> 350.874 | G17: ='[1]5.2 附表2000-2050EU27_Import_CHZ'!BV$55*'CBAM - Mechanism Rules'!$B17 -> 410.742 | H17: ='[1]5.2 附表2000-2050EU27_Import_CHZ'!BW$55*'CBAM - Mechanism Rules'!$B17 -> 575.865 | I17: ='[1]5.2 附表2000-2050EU27_Import_CHZ'!BX$55*'CBAM - Mechanism Rules'!$B17 -> 607.842 | J17: ='[1]5.2 附表2000-2050EU27_Import_CHZ'!BY$55*'CBAM - Mechanism Rules'!$B17 -> 615.159 | K17: ='[1]5.2 附表2000-2050EU27_Import_CHZ'!BZ$55*'CBAM - Mechanism Rules'!$B17 -> 622.179 | L17: ='[1]5.2 附表2000-2050EU27_Import_CHZ'!CA$55*'CBAM - Mechanism Rules'!$B17 -> 628.938 | M17: ='[1]5.2 附表2000-2050EU27_Import_CHZ'!CB$55*'CBAM - Mechanism Rules'!$B17 -> 635.445 | ... AJ17: ='[1]5.2 附表2000-2050EU27_Import_CHZ'!CY$55*'CBAM - Mechanism Rules'!$B17 -> 742.797
B18: =('[1]5.3.1 钢铁行业参数数据库'!F143+'[1]5.3.1 钢铁行业参数数据库'!F144)/'[1]5.3.1 钢铁行业参数数据库'!F146 -> 0.0010340899 | C18: Trade volume | D18: =[1]对照表!$B$10 -> Steel (DRI-EAF route) | F18: ='[1]5.2 附表2000-2050EU27_Import_CHZ'!BU$55*'CBAM - Mechanism Rules'!$B18 -> 0.40315028 | G18: ='[1]5.2 附表2000-2050EU27_Import_CHZ'!BV$55*'CBAM - Mechanism Rules'!$B18 -> 0.47193793 | H18: ='[1]5.2 附表2000-2050EU27_Import_CHZ'!BW$55*'CBAM - Mechanism Rules'!$B18 -> 0.6616624 | I18: ='[1]5.2 附表2000-2050EU27_Import_CHZ'!BX$55*'CBAM - Mechanism Rules'!$B18 -> 0.69840362 | J18: ='[1]5.2 附表2000-2050EU27_Import_CHZ'!BY$55*'CBAM - Mechanism Rules'!$B18 -> 0.70681077 | K18: ='[1]5.2 附表2000-2050EU27_Import_CHZ'!BZ$55*'CBAM - Mechanism Rules'!$B18 -> 0.71487667 | L18: ='[1]5.2 附表2000-2050EU27_Import_CHZ'!CA$55*'CBAM - Mechanism Rules'!$B18 -> 0.72264268 | M18: ='[1]5.2 附表2000-2050EU27_Import_CHZ'!CB$55*'CBAM - Mechanism Rules'!$B18 -> 0.73011915 | ... AJ18: ='[1]5.2 附表2000-2050EU27_Import_CHZ'!CY$55*'CBAM - Mechanism Rules'!$B18 -> 0.85346539
B19: =1-B17-B18 -> 0.09896591 | C19: Trade volume | D19: =[1]对照表!$B$11 -> Steel (Scrap-EAF route) | F19: ='[1]5.2 附表2000-2050EU27_Import_CHZ'!BU$55*'CBAM - Mechanism Rules'!$B19 -> 38.58285 | G19: ='[1]5.2 附表2000-2050EU27_Import_CHZ'!BV$55*'CBAM - Mechanism Rules'!$B19 -> 45.166062 | H19: ='[1]5.2 附表2000-2050EU27_Import_CHZ'!BW$55*'CBAM - Mechanism Rules'!$B19 -> 63.323338 | I19: ='[1]5.2 附表2000-2050EU27_Import_CHZ'!BX$55*'CBAM - Mechanism Rules'!$B19 -> 66.839596 | J19: ='[1]5.2 附表2000-2050EU27_Import_CHZ'!BY$55*'CBAM - Mechanism Rules'!$B19 -> 67.644189 | K19: ='[1]5.2 附表2000-2050EU27_Import_CHZ'!BZ$55*'CBAM - Mechanism Rules'!$B19 -> 68.416123 | L19: ='[1]5.2 附表2000-2050EU27_Import_CHZ'!CA$55*'CBAM - Mechanism Rules'!$B19 -> 69.159357 | M19: ='[1]5.2 附表2000-2050EU27_Import_CHZ'!CB$55*'CBAM - Mechanism Rules'!$B19 -> 69.874881 | ... AJ19: ='[1]5.2 附表2000-2050EU27_Import_CHZ'!CY$55*'CBAM - Mechanism Rules'!$B19 -> 81.679535
C20: Trade volume | D20: Total | F20: =SUM(F10:F19) -> 390.6 | G20: =SUM(G10:G19) -> 456.89 | H20: =SUM(H10:H19) -> 646.75 | I20: =SUM(I10:I19) -> 677.5 | J20: =SUM(J10:J19) -> 685.61 | K20: =SUM(K10:K19) -> 693.39 | L20: =SUM(L10:L19) -> 700.89 | M20: =SUM(M10:M19) -> 708.09 | ... AJ20: =SUM(AJ10:AJ19) -> 827.28
B22: EU carbon market free allowance benchmark | F22: 2020 | G22: 2021 | H22: 2022 | I22: 2023 | J22: 2024 | K22: 2025 | L22: 2026 | M22: 2027 | N22: 2028 | O22: 2029 | P22: 2030 | Q22: 2031 | R22: 2032 | S22: 2033 | T22: 2034 | U22: 2035 | V22: 2036 | W22: 2037 | X22: 2038 | Y22: 2039 | Z22: 2040 | AA22: 2041 | AB22: 2042 | AC22: 2043 | AD22: 2044 | AE22: 2045 | AF22: 2046 | AG22: 2047 | AH22: 2048 | AI22: 2049 | AJ22: 2050
C23: BAU | D23: =[1]对照表!$B$2 -> Sintered ore | E23: =C23&D23 -> BAUSintered ore | F23: =VLOOKUP($E23,'[1]5.2 附表1'!$E$29:$BC$60,F$2+1,) -> 0.171 | G23: =VLOOKUP($E23,'[1]5.2 附表1'!$E$29:$BC$60,G$2+1,) -> 0.157 | H23: =VLOOKUP($E23,'[1]5.2 附表1'!$E$29:$BC$60,H$2+1,) -> 0.157 | I23: =VLOOKUP($E23,'[1]5.2 附表1'!$E$29:$BC$60,I$2+1,) -> 0.157 | J23: =VLOOKUP($E23,'[1]5.2 附表1'!$E$29:$BC$60,J$2+1,) -> 0.157 | K23: =VLOOKUP($E23,'[1]5.2 附表1'!$E$29:$BC$60,K$2+1,) -> 0.157 | L23: =VLOOKUP($E23,'[1]5.2 附表1'!$E$29:$BC$60,L$2+1,) -> 0.11628 | M23: =VLOOKUP($E23,'[1]5.2 附表1'!$E$29:$BC$60,M$2+1,) -> 0.11628 | ... T23: =VLOOKUP($E23,'[1]5.2 附表1'!$E$29:$BC$60,T$2+1,) -> 0.1026 | U23: 0 | V23: 0 | W23: 0 | X23: 0 | Y23: 0 | Z23: 0 | AA23: 0 | AB23: 0 | AC23: 0 | AD23: 0 | AE23: 0 | AF23: 0 | AG23: 0 | AH23: 0 | AI23: 0 | AJ23: 0
C24: BAU | D24: =[1]对照表!$B$3 -> Alloys | E24: =C24&D24 -> BAUAlloys | F24: =VLOOKUP($E24,'[1]5.2 附表1'!$E$29:$BC$60,F$2+1,) -> 0.2052 | G24: =VLOOKUP($E24,'[1]5.2 附表1'!$E$29:$BC$60,G$2+1,) -> 0.1884 | H24: =VLOOKUP($E24,'[1]5.2 附表1'!$E$29:$BC$60,H$2+1,) -> 0.1884 | I24: =VLOOKUP($E24,'[1]5.2 附表1'!$E$29:$BC$60,I$2+1,) -> 0.1884 | J24: =VLOOKUP($E24,'[1]5.2 附表1'!$E$29:$BC$60,J$2+1,) -> 0.1884 | K24: =VLOOKUP($E24,'[1]5.2 附表1'!$E$29:$BC$60,K$2+1,) -> 0.1884 | L24: =VLOOKUP($E24,'[1]5.2 附表1'!$E$29:$BC$60,L$2+1,) -> 0.139536 | M24: =VLOOKUP($E24,'[1]5.2 附表1'!$E$29:$BC$60,M$2+1,) -> 0.139536 | ... T24: =VLOOKUP($E24,'[1]5.2 附表1'!$E$29:$BC$60,T$2+1,) -> 0.12312 | U24: 0 | V24: 0 | W24: 0 | X24: 0 | Y24: 0 | Z24: 0 | AA24: 0 | AB24: 0 | AC24: 0 | AD24: 0 | AE24: 0 | AF24: 0 | AG24: 0 | AH24: 0 | AI24: 0 | AJ24: 0
C25: BAU | D25: =[1]对照表!$B$4 -> Pig iron (BF) | E25: =C25&D25 -> BAUPig iron (BF) | F25: =VLOOKUP($E25,'[1]5.2 附表1'!$E$29:$BC$60,F$2+1,) -> 1.328 | G25: =VLOOKUP($E25,'[1]5.2 附表1'!$E$29:$BC$60,G$2+1,) -> 1.288 | H25: =VLOOKUP($E25,'[1]5.2 附表1'!$E$29:$BC$60,H$2+1,) -> 1.288 | I25: =VLOOKUP($E25,'[1]5.2 附表1'!$E$29:$BC$60,I$2+1,) -> 1.288 | J25: =VLOOKUP($E25,'[1]5.2 附表1'!$E$29:$BC$60,J$2+1,) -> 1.288 | K25: =VLOOKUP($E25,'[1]5.2 附表1'!$E$29:$BC$60,K$2+1,) -> 1.288 | L25: =VLOOKUP($E25,'[1]5.2 附表1'!$E$29:$BC$60,L$2+1,) -> 1.27488 | M25: =VLOOKUP($E25,'[1]5.2 附表1'!$E$29:$BC$60,M$2+1,) -> 1.27488 | ... T25: =VLOOKUP($E25,'[1]5.2 附表1'!$E$29:$BC$60,T$2+1,) -> 1.2616 | U25: 0 | V25: 0 | W25: 0 | X25: 0 | Y25: 0 | Z25: 0 | AA25: 0 | AB25: 0 | AC25: 0 | AD25: 0 | AE25: 0 | AF25: 0 | AG25: 0 | AH25: 0 | AI25: 0 | AJ25: 0
C26: BAU | D26: =[1]对照表!$B$5 -> Pig iron (smelting reduction) | E26: =C26&D26 -> BAUPig iron (smelting reduction) | F26: =VLOOKUP($E26,'[1]5.2 附表1'!$E$29:$BC$60,F$2+1,) -> 0.2736 | G26: =VLOOKUP($E26,'[1]5.2 附表1'!$E$29:$BC$60,G$2+1,) -> 0.2512 | H26: =VLOOKUP($E26,'[1]5.2 附表1'!$E$29:$BC$60,H$2+1,) -> 0.2512 | I26: =VLOOKUP($E26,'[1]5.2 附表1'!$E$29:$BC$60,I$2+1,) -> 0.2512 | J26: =VLOOKUP($E26,'[1]5.2 附表1'!$E$29:$BC$60,J$2+1,) -> 0.2512 | K26: =VLOOKUP($E26,'[1]5.2 附表1'!$E$29:$BC$60,K$2+1,) -> 0.2512 | L26: =VLOOKUP($E26,'[1]5.2 附表1'!$E$29:$BC$60,L$2+1,) -> 0.186048 | M26: =VLOOKUP($E26,'[1]5.2 附表1'!$E$29:$BC$60,M$2+1,) -> 0.186048 | ... T26: =VLOOKUP($E26,'[1]5.2 附表1'!$E$29:$BC$60,T$2+1,) -> 0.16416 | U26: 0 | V26: 0 | W26: 0 | X26: 0 | Y26: 0 | Z26: 0 | AA26: 0 | AB26: 0 | AC26: 0 | AD26: 0 | AE26: 0 | AF26: 0 | AG26: 0 | AH26: 0 | AI26: 0 | AJ26: 0
C27: BAU | D27: =[1]对照表!$B$6 -> DRI | E27: =C27&D27 -> BAUDRI | F27: =VLOOKUP($E27,'[1]5.2 附表1'!$E$29:$BC$60,F$2+1,) -> 0.2736 | G27: =VLOOKUP($E27,'[1]5.2 附表1'!$E$29:$BC$60,G$2+1,) -> 0.2512 | H27: =VLOOKUP($E27,'[1]5.2 附表1'!$E$29:$BC$60,H$2+1,) -> 0.2512 | I27: =VLOOKUP($E27,'[1]5.2 附表1'!$E$29:$BC$60,I$2+1,) -> 0.2512 | J27: =VLOOKUP($E27,'[1]5.2 附表1'!$E$29:$BC$60,J$2+1,) -> 0.2512 | K27: =VLOOKUP($E27,'[1]5.2 附表1'!$E$29:$BC$60,K$2+1,) -> 0.2512 | L27: =VLOOKUP($E27,'[1]5.2 附表1'!$E$29:$BC$60,L$2+1,) -> 0.186048 | M27: =VLOOKUP($E27,'[1]5.2 附表1'!$E$29:$BC$60,M$2+1,) -> 0.186048 | ... T27: =VLOOKUP($E27,'[1]5.2 附表1'!$E$29:$BC$60,T$2+1,) -> 0.16416 | U27: 0 | V27: 0 | W27: 0 | X27: 0 | Y27: 0 | Z27: 0 | AA27: 0 | AB27: 0 | AC27: 0 | AD27: 0 | AE27: 0 | AF27: 0 | AG27: 0 | AH27: 0 | AI27: 0 | AJ27: 0
C28: BAU | D28: =[1]对照表!$B$7 -> Crude steel (BOF route) | E28: =C28&D28 -> BAUCrude steel (BOF route) | F28: =VLOOKUP($E28,'[1]5.2 附表1'!$E$29:$BC$60,F$2+1,) -> 1.6016 | G28: =VLOOKUP($E28,'[1]5.2 附表1'!$E$29:$BC$60,G$2+1,) -> 1.5392 | H28: =VLOOKUP($E28,'[1]5.2 附表1'!$E$29:$BC$60,H$2+1,) -> 1.5392 | I28: =VLOOKUP($E28,'[1]5.2 附表1'!$E$29:$BC$60,I$2+1,) -> 1.5392 | J28: =VLOOKUP($E28,'[1]5.2 附表1'!$E$29:$BC$60,J$2+1,) -> 1.5392 | K28: =VLOOKUP($E28,'[1]5.2 附表1'!$E$29:$BC$60,K$2+1,) -> 1.5392 | L28: =VLOOKUP($E28,'[1]5.2 附表1'!$E$29:$BC$60,L$2+1,) -> 1.460928 | M28: =VLOOKUP($E28,'[1]5.2 附表1'!$E$29:$BC$60,M$2+1,) -> 1.460928 | ... T28: =VLOOKUP($E28,'[1]5.2 附表1'!$E$29:$BC$60,T$2+1,) -> 1.42576 | U28: 0 | V28: 0 | W28: 0 | X28: 0 | Y28: 0 | Z28: 0 | AA28: 0 | AB28: 0 | AC28: 0 | AD28: 0 | AE28: 0 | AF28: 0 | AG28: 0 | AH28: 0 | AI28: 0 | AJ28: 0
C29: BAU | D29: =[1]对照表!$B$8 -> Crude steel (EAF route) | E29: =C29&D29 -> BAUCrude steel (EAF route) | F29: =VLOOKUP($E29,'[1]5.2 附表1'!$E$29:$BC$60,F$2+1,) -> 0.3175 | G29: =VLOOKUP($E29,'[1]5.2 附表1'!$E$29:$BC$60,G$2+1,) -> 0.2415 | H29: =VLOOKUP($E29,'[1]5.2 附表1'!$E$29:$BC$60,H$2+1,) -> 0.2415 | I29: =VLOOKUP($E29,'[1]5.2 附表1'!$E$29:$BC$60,I$2+1,) -> 0.2415 | J29: =VLOOKUP($E29,'[1]5.2 附表1'!$E$29:$BC$60,J$2+1,) -> 0.2415 | K29: =VLOOKUP($E29,'[1]5.2 附表1'!$E$29:$BC$60,K$2+1,) -> 0.2415 | L29: =VLOOKUP($E29,'[1]5.2 附表1'!$E$29:$BC$60,L$2+1,) -> 0.2159 | M29: =VLOOKUP($E29,'[1]5.2 附表1'!$E$29:$BC$60,M$2+1,) -> 0.2159 | ... T29: =VLOOKUP($E29,'[1]5.2 附表1'!$E$29:$BC$60,T$2+1,) -> 0.1905 | U29: 0 | V29: 0 | W29: 0 | X29: 0 | Y29: 0 | Z29: 0 | AA29: 0 | AB29: 0 | AC29: 0 | AD29: 0 | AE29: 0 | AF29: 0 | AG29: 0 | AH29: 0 | AI29: 0 | AJ29: 0
C30: BAU | D30: =[1]对照表!$B$9 -> Steel (BF-BOF route) | E30: =C30&D30 -> BAUSteel (BF-BOF route) | F30: =VLOOKUP($E30,'[1]5.2 附表1'!$E$29:$BC$60,F$2+1,) -> 1.7825808 | G30: =VLOOKUP($E30,'[1]5.2 附表1'!$E$29:$BC$60,G$2+1,) -> 1.7131296 | H30: =VLOOKUP($E30,'[1]5.2 附表1'!$E$29:$BC$60,H$2+1,) -> 1.7131296 | I30: =VLOOKUP($E30,'[1]5.2 附表1'!$E$29:$BC$60,I$2+1,) -> 1.7131296 | J30: =VLOOKUP($E30,'[1]5.2 附表1'!$E$29:$BC$60,J$2+1,) -> 1.7131296 | K30: =VLOOKUP($E30,'[1]5.2 附表1'!$E$29:$BC$60,K$2+1,) -> 1.7131296 | L30: =VLOOKUP($E30,'[1]5.2 附表1'!$E$29:$BC$60,L$2+1,) -> 1.6260129 | M30: =VLOOKUP($E30,'[1]5.2 附表1'!$E$29:$BC$60,M$2+1,) -> 1.6260129 | ... T30: =VLOOKUP($E30,'[1]5.2 附表1'!$E$29:$BC$60,T$2+1,) -> 1.5868709 | U30: 0 | V30: 0 | W30: 0 | X30: 0 | Y30: 0 | Z30: 0 | AA30: 0 | AB30: 0 | AC30: 0 | AD30: 0 | AE30: 0 | AF30: 0 | AG30: 0 | AH30: 0 | AI30: 0 | AJ30: 0
C31: BAU | D31: =[1]对照表!$B$10 -> Steel (DRI-EAF route) | E31: =C31&D31 -> BAUSteel (DRI-EAF route) | F31: =VLOOKUP($E31,'[1]5.2 附表1'!$E$29:$BC$60,F$2+1,) -> 0.5911 | G31: =VLOOKUP($E31,'[1]5.2 附表1'!$E$29:$BC$60,G$2+1,) -> 0.4927 | H31: =VLOOKUP($E31,'[1]5.2 附表1'!$E$29:$BC$60,H$2+1,) -> 0.4927 | I31: =VLOOKUP($E31,'[1]5.2 附表1'!$E$29:$BC$60,I$2+1,) -> 0.4927 | J31: =VLOOKUP($E31,'[1]5.2 附表1'!$E$29:$BC$60,J$2+1,) -> 0.4927 | K31: =VLOOKUP($E31,'[1]5.2 附表1'!$E$29:$BC$60,K$2+1,) -> 0.4927 | L31: =VLOOKUP($E31,'[1]5.2 附表1'!$E$29:$BC$60,L$2+1,) -> 0.401948 | M31: =VLOOKUP($E31,'[1]5.2 附表1'!$E$29:$BC$60,M$2+1,) -> 0.401948 | ... T31: =VLOOKUP($E31,'[1]5.2 附表1'!$E$29:$BC$60,T$2+1,) -> 0.35466 | U31: 0 | V31: 0 | W31: 0 | X31: 0 | Y31: 0 | Z31: 0 | AA31: 0 | AB31: 0 | AC31: 0 | AD31: 0 | AE31: 0 | AF31: 0 | AG31: 0 | AH31: 0 | AI31: 0 | AJ31: 0
C32: BAU | D32: =[1]对照表!$B$11 -> Steel (Scrap-EAF route) | E32: =C32&D32 -> BAUSteel (Scrap-EAF route) | F32: =VLOOKUP($E32,'[1]5.2 附表1'!$E$29:$BC$60,F$2+1,) -> 0.325 | G32: =VLOOKUP($E32,'[1]5.2 附表1'!$E$29:$BC$60,G$2+1,) -> 0.282 | H32: =VLOOKUP($E32,'[1]5.2 附表1'!$E$29:$BC$60,H$2+1,) -> 0.282 | I32: =VLOOKUP($E32,'[1]5.2 附表1'!$E$29:$BC$60,I$2+1,) -> 0.282 | J32: =VLOOKUP($E32,'[1]5.2 附表1'!$E$29:$BC$60,J$2+1,) -> 0.282 | K32: =VLOOKUP($E32,'[1]5.2 附表1'!$E$29:$BC$60,K$2+1,) -> 0.282 | L32: =VLOOKUP($E32,'[1]5.2 附表1'!$E$29:$BC$60,L$2+1,) -> 0.221 | M32: =VLOOKUP($E32,'[1]5.2 附表1'!$E$29:$BC$60,M$2+1,) -> 0.221 | ... T32: =VLOOKUP($E32,'[1]5.2 附表1'!$E$29:$BC$60,T$2+1,) -> 0.195 | U32: 0 | V32: 0 | W32: 0 | X32: 0 | Y32: 0 | Z32: 0 | AA32: 0 | AB32: 0 | AC32: 0 | AD32: 0 | AE32: 0 | AF32: 0 | AG32: 0 | AH32: 0 | AI32: 0 | AJ32: 0
C34: DCS | D34: Sintered ore | E34: =C34&D34 -> DCSSintered ore | F34: =VLOOKUP($E34,'[1]5.2 附表1'!$E$29:$BC$60,F$2+1,) -> 0.171 | G34: =VLOOKUP($E34,'[1]5.2 附表1'!$E$29:$BC$60,G$2+1,) -> 0.157 | H34: =VLOOKUP($E34,'[1]5.2 附表1'!$E$29:$BC$60,H$2+1,) -> 0.157 | I34: =VLOOKUP($E34,'[1]5.2 附表1'!$E$29:$BC$60,I$2+1,) -> 0.157 | J34: =VLOOKUP($E34,'[1]5.2 附表1'!$E$29:$BC$60,J$2+1,) -> 0.157 | K34: =VLOOKUP($E34,'[1]5.2 附表1'!$E$29:$BC$60,K$2+1,) -> 0.157 | L34: =VLOOKUP($E34,'[1]5.2 附表1'!$E$29:$BC$60,L$2+1,) -> 0.1026 | M34: =VLOOKUP($E34,'[1]5.2 附表1'!$E$29:$BC$60,M$2+1,) -> 0.1026 | ... T34: =VLOOKUP($E34,'[1]5.2 附表1'!$E$29:$BC$60,T$2+1,) -> 0.0855 | U34: 0 | V34: 0 | W34: 0 | X34: 0 | Y34: 0 | Z34: 0 | AA34: 0 | AB34: 0 | AC34: 0 | AD34: 0 | AE34: 0 | AF34: 0 | AG34: 0 | AH34: 0 | AI34: 0 | AJ34: 0
C35: DCS | D35: Alloys | E35: =C35&D35 -> DCSAlloys | F35: =VLOOKUP($E35,'[1]5.2 附表1'!$E$29:$BC$60,F$2+1,) -> 0.2052 | G35: =VLOOKUP($E35,'[1]5.2 附表1'!$E$29:$BC$60,G$2+1,) -> 0.1884 | H35: =VLOOKUP($E35,'[1]5.2 附表1'!$E$29:$BC$60,H$2+1,) -> 0.1884 | I35: =VLOOKUP($E35,'[1]5.2 附表1'!$E$29:$BC$60,I$2+1,) -> 0.1884 | J35: =VLOOKUP($E35,'[1]5.2 附表1'!$E$29:$BC$60,J$2+1,) -> 0.1884 | K35: =VLOOKUP($E35,'[1]5.2 附表1'!$E$29:$BC$60,K$2+1,) -> 0.1884 | L35: =VLOOKUP($E35,'[1]5.2 附表1'!$E$29:$BC$60,L$2+1,) -> 0.12312 | M35: =VLOOKUP($E35,'[1]5.2 附表1'!$E$29:$BC$60,M$2+1,) -> 0.12312 | ... T35: =VLOOKUP($E35,'[1]5.2 附表1'!$E$29:$BC$60,T$2+1,) -> 0.1026 | U35: 0 | V35: 0 | W35: 0 | X35: 0 | Y35: 0 | Z35: 0 | AA35: 0 | AB35: 0 | AC35: 0 | AD35: 0 | AE35: 0 | AF35: 0 | AG35: 0 | AH35: 0 | AI35: 0 | AJ35: 0
C36: DCS | D36: Pig iron (BF) | E36: =C36&D36 -> DCSPig iron (BF) | F36: =VLOOKUP($E36,'[1]5.2 附表1'!$E$29:$BC$60,F$2+1,) -> 1.328 | G36: =VLOOKUP($E36,'[1]5.2 附表1'!$E$29:$BC$60,G$2+1,) -> 1.288 | H36: =VLOOKUP($E36,'[1]5.2 附表1'!$E$29:$BC$60,H$2+1,) -> 1.288 | I36: =VLOOKUP($E36,'[1]5.2 附表1'!$E$29:$BC$60,I$2+1,) -> 1.288 | J36: =VLOOKUP($E36,'[1]5.2 附表1'!$E$29:$BC$60,J$2+1,) -> 1.288 | K36: =VLOOKUP($E36,'[1]5.2 附表1'!$E$29:$BC$60,K$2+1,) -> 1.288 | L36: =VLOOKUP($E36,'[1]5.2 附表1'!$E$29:$BC$60,L$2+1,) -> 1.23504 | M36: =VLOOKUP($E36,'[1]5.2 附表1'!$E$29:$BC$60,M$2+1,) -> 1.23504 | ... T36: =VLOOKUP($E36,'[1]5.2 附表1'!$E$29:$BC$60,T$2+1,) -> 1.2118 | U36: 0 | V36: 0 | W36: 0 | X36: 0 | Y36: 0 | Z36: 0 | AA36: 0 | AB36: 0 | AC36: 0 | AD36: 0 | AE36: 0 | AF36: 0 | AG36: 0 | AH36: 0 | AI36: 0 | AJ36: 0
C37: DCS | D37: Pig iron (smelting reduction) | E37: =C37&D37 -> DCSPig iron (smelting reduction) | F37: =VLOOKUP($E37,'[1]5.2 附表1'!$E$29:$BC$60,F$2+1,) -> 0.2736 | G37: =VLOOKUP($E37,'[1]5.2 附表1'!$E$29:$BC$60,G$2+1,) -> 0.2512 | H37: =VLOOKUP($E37,'[1]5.2 附表1'!$E$29:$BC$60,H$2+1,) -> 0.2512 | I37: =VLOOKUP($E37,'[1]5.2 附表1'!$E$29:$BC$60,I$2+1,) -> 0.2512 | J37: =VLOOKUP($E37,'[1]5.2 附表1'!$E$29:$BC$60,J$2+1,) -> 0.2512 | K37: =VLOOKUP($E37,'[1]5.2 附表1'!$E$29:$BC$60,K$2+1,) -> 0.2512 | L37: =VLOOKUP($E37,'[1]5.2 附表1'!$E$29:$BC$60,L$2+1,) -> 0.16416 | M37: =VLOOKUP($E37,'[1]5.2 附表1'!$E$29:$BC$60,M$2+1,) -> 0.16416 | ... T37: =VLOOKUP($E37,'[1]5.2 附表1'!$E$29:$BC$60,T$2+1,) -> 0.1368 | U37: 0 | V37: 0 | W37: 0 | X37: 0 | Y37: 0 | Z37: 0 | AA37: 0 | AB37: 0 | AC37: 0 | AD37: 0 | AE37: 0 | AF37: 0 | AG37: 0 | AH37: 0 | AI37: 0 | AJ37: 0
C38: DCS | D38: DRI | E38: =C38&D38 -> DCSDRI | F38: =VLOOKUP($E38,'[1]5.2 附表1'!$E$29:$BC$60,F$2+1,) -> 0.2736 | G38: =VLOOKUP($E38,'[1]5.2 附表1'!$E$29:$BC$60,G$2+1,) -> 0.2512 | H38: =VLOOKUP($E38,'[1]5.2 附表1'!$E$29:$BC$60,H$2+1,) -> 0.2512 | I38: =VLOOKUP($E38,'[1]5.2 附表1'!$E$29:$BC$60,I$2+1,) -> 0.2512 | J38: =VLOOKUP($E38,'[1]5.2 附表1'!$E$29:$BC$60,J$2+1,) -> 0.2512 | K38: =VLOOKUP($E38,'[1]5.2 附表1'!$E$29:$BC$60,K$2+1,) -> 0.2512 | L38: =VLOOKUP($E38,'[1]5.2 附表1'!$E$29:$BC$60,L$2+1,) -> 0.16416 | M38: =VLOOKUP($E38,'[1]5.2 附表1'!$E$29:$BC$60,M$2+1,) -> 0.16416 | ... T38: =VLOOKUP($E38,'[1]5.2 附表1'!$E$29:$BC$60,T$2+1,) -> 0.1368 | U38: 0 | V38: 0 | W38: 0 | X38: 0 | Y38: 0 | Z38: 0 | AA38: 0 | AB38: 0 | AC38: 0 | AD38: 0 | AE38: 0 | AF38: 0 | AG38: 0 | AH38: 0 | AI38: 0 | AJ38: 0
C39: DCS | D39: Crude steel (BOF route) | E39: =C39&D39 -> DCSCrude steel (BOF route) | F39: =VLOOKUP($E39,'[1]5.2 附表1'!$E$29:$BC$60,F$2+1,) -> 1.6016 | G39: =VLOOKUP($E39,'[1]5.2 附表1'!$E$29:$BC$60,G$2+1,) -> 1.5392 | H39: =VLOOKUP($E39,'[1]5.2 附表1'!$E$29:$BC$60,H$2+1,) -> 1.5392 | I39: =VLOOKUP($E39,'[1]5.2 附表1'!$E$29:$BC$60,I$2+1,) -> 1.5392 | J39: =VLOOKUP($E39,'[1]5.2 附表1'!$E$29:$BC$60,J$2+1,) -> 1.5392 | K39: =VLOOKUP($E39,'[1]5.2 附表1'!$E$29:$BC$60,K$2+1,) -> 1.5392 | L39: =VLOOKUP($E39,'[1]5.2 附表1'!$E$29:$BC$60,L$2+1,) -> 1.3992 | M39: =VLOOKUP($E39,'[1]5.2 附表1'!$E$29:$BC$60,M$2+1,) -> 1.3992 | ... T39: =VLOOKUP($E39,'[1]5.2 附表1'!$E$29:$BC$60,T$2+1,) -> 1.3486 | U39: 0 | V39: 0 | W39: 0 | X39: 0 | Y39: 0 | Z39: 0 | AA39: 0 | AB39: 0 | AC39: 0 | AD39: 0 | AE39: 0 | AF39: 0 | AG39: 0 | AH39: 0 | AI39: 0 | AJ39: 0
C40: DCS | D40: Crude steel (EAF route) | E40: =C40&D40 -> DCSCrude steel (EAF route) | F40: =VLOOKUP($E40,'[1]5.2 附表1'!$E$29:$BC$60,F$2+1,) -> 0.3175 | G40: =VLOOKUP($E40,'[1]5.2 附表1'!$E$29:$BC$60,G$2+1,) -> 0.2415 | H40: =VLOOKUP($E40,'[1]5.2 附表1'!$E$29:$BC$60,H$2+1,) -> 0.2415 | I40: =VLOOKUP($E40,'[1]5.2 附表1'!$E$29:$BC$60,I$2+1,) -> 0.2415 | J40: =VLOOKUP($E40,'[1]5.2 附表1'!$E$29:$BC$60,J$2+1,) -> 0.2415 | K40: =VLOOKUP($E40,'[1]5.2 附表1'!$E$29:$BC$60,K$2+1,) -> 0.2415 | L40: =VLOOKUP($E40,'[1]5.2 附表1'!$E$29:$BC$60,L$2+1,) -> 0.1905 | M40: =VLOOKUP($E40,'[1]5.2 附表1'!$E$29:$BC$60,M$2+1,) -> 0.1905 | ... T40: =VLOOKUP($E40,'[1]5.2 附表1'!$E$29:$BC$60,T$2+1,) -> 0.15875 | U40: 0 | V40: 0 | W40: 0 | X40: 0 | Y40: 0 | Z40: 0 | AA40: 0 | AB40: 0 | AC40: 0 | AD40: 0 | AE40: 0 | AF40: 0 | AG40: 0 | AH40: 0 | AI40: 0 | AJ40: 0
C41: DCS | D41: Steel (BF-BOF route) | E41: =C41&D41 -> DCSSteel (BF-BOF route) | F41: =VLOOKUP($E41,'[1]5.2 附表1'!$E$29:$BC$60,F$2+1,) -> 1.7825808 | G41: =VLOOKUP($E41,'[1]5.2 附表1'!$E$29:$BC$60,G$2+1,) -> 1.7131296 | H41: =VLOOKUP($E41,'[1]5.2 附表1'!$E$29:$BC$60,H$2+1,) -> 1.7131296 | I41: =VLOOKUP($E41,'[1]5.2 附表1'!$E$29:$BC$60,I$2+1,) -> 1.7131296 | J41: =VLOOKUP($E41,'[1]5.2 附表1'!$E$29:$BC$60,J$2+1,) -> 1.7131296 | K41: =VLOOKUP($E41,'[1]5.2 附表1'!$E$29:$BC$60,K$2+1,) -> 1.7131296 | L41: =VLOOKUP($E41,'[1]5.2 附表1'!$E$29:$BC$60,L$2+1,) -> 1.5573096 | M41: =VLOOKUP($E41,'[1]5.2 附表1'!$E$29:$BC$60,M$2+1,) -> 1.5573096 | ... T41: =VLOOKUP($E41,'[1]5.2 附表1'!$E$29:$BC$60,T$2+1,) -> 1.5009918 | U41: 0 | V41: 0 | W41: 0 | X41: 0 | Y41: 0 | Z41: 0 | AA41: 0 | AB41: 0 | AC41: 0 | AD41: 0 | AE41: 0 | AF41: 0 | AG41: 0 | AH41: 0 | AI41: 0 | AJ41: 0
C42: DCS | D42: Steel (DRI-EAF route) | E42: =C42&D42 -> DCSSteel (DRI-EAF route) | F42: =VLOOKUP($E42,'[1]5.2 附表1'!$E$29:$BC$60,F$2+1,) -> 0.5911 | G42: =VLOOKUP($E42,'[1]5.2 附表1'!$E$29:$BC$60,G$2+1,) -> 0.4927 | H42: =VLOOKUP($E42,'[1]5.2 附表1'!$E$29:$BC$60,H$2+1,) -> 0.4927 | I42: =VLOOKUP($E42,'[1]5.2 附表1'!$E$29:$BC$60,I$2+1,) -> 0.4927 | J42: =VLOOKUP($E42,'[1]5.2 附表1'!$E$29:$BC$60,J$2+1,) -> 0.4927 | K42: =VLOOKUP($E42,'[1]5.2 附表1'!$E$29:$BC$60,K$2+1,) -> 0.4927 | L42: =VLOOKUP($E42,'[1]5.2 附表1'!$E$29:$BC$60,L$2+1,) -> 0.35466 | M42: =VLOOKUP($E42,'[1]5.2 附表1'!$E$29:$BC$60,M$2+1,) -> 0.35466 | ... T42: =VLOOKUP($E42,'[1]5.2 附表1'!$E$29:$BC$60,T$2+1,) -> 0.29555 | U42: 0 | V42: 0 | W42: 0 | X42: 0 | Y42: 0 | Z42: 0 | AA42: 0 | AB42: 0 | AC42: 0 | AD42: 0 | AE42: 0 | AF42: 0 | AG42: 0 | AH42: 0 | AI42: 0 | AJ42: 0
C43: DCS | D43: Steel (Scrap-EAF route) | E43: =C43&D43 -> DCSSteel (Scrap-EAF route) | F43: =VLOOKUP($E43,'[1]5.2 附表1'!$E$29:$BC$60,F$2+1,) -> 0.325 | G43: =VLOOKUP($E43,'[1]5.2 附表1'!$E$29:$BC$60,G$2+1,) -> 0.282 | H43: =VLOOKUP($E43,'[1]5.2 附表1'!$E$29:$BC$60,H$2+1,) -> 0.282 | I43: =VLOOKUP($E43,'[1]5.2 附表1'!$E$29:$BC$60,I$2+1,) -> 0.282 | J43: =VLOOKUP($E43,'[1]5.2 附表1'!$E$29:$BC$60,J$2+1,) -> 0.282 | K43: =VLOOKUP($E43,'[1]5.2 附表1'!$E$29:$BC$60,K$2+1,) -> 0.282 | L43: =VLOOKUP($E43,'[1]5.2 附表1'!$E$29:$BC$60,L$2+1,) -> 0.195 | M43: =VLOOKUP($E43,'[1]5.2 附表1'!$E$29:$BC$60,M$2+1,) -> 0.195 | ... T43: =VLOOKUP($E43,'[1]5.2 附表1'!$E$29:$BC$60,T$2+1,) -> 0.1625 | U43: 0 | V43: 0 | W43: 0 | X43: 0 | Y43: 0 | Z43: 0 | AA43: 0 | AB43: 0 | AC43: 0 | AD43: 0 | AE43: 0 | AF43: 0 | AG43: 0 | AH43: 0 | AI43: 0 | AJ43: 0
C45: NES | D45: Sintered ore | E45: =C45&D45 -> NESSintered ore | F45: =VLOOKUP($E45,'[1]5.2 附表1'!$E$29:$BC$60,F$2+1,) -> 0.171 | G45: =VLOOKUP($E45,'[1]5.2 附表1'!$E$29:$BC$60,G$2+1,) -> 0.157 | H45: =VLOOKUP($E45,'[1]5.2 附表1'!$E$29:$BC$60,H$2+1,) -> 0.157 | I45: =VLOOKUP($E45,'[1]5.2 附表1'!$E$29:$BC$60,I$2+1,) -> 0.157 | J45: =VLOOKUP($E45,'[1]5.2 附表1'!$E$29:$BC$60,J$2+1,) -> 0.157 | K45: =VLOOKUP($E45,'[1]5.2 附表1'!$E$29:$BC$60,K$2+1,) -> 0.157 | L45: =VLOOKUP($E45,'[1]5.2 附表1'!$E$29:$BC$60,L$2+1,) -> 0.0855 | M45: =VLOOKUP($E45,'[1]5.2 附表1'!$E$29:$BC$60,M$2+1,) -> 0.0855 | ... T45: =VLOOKUP($E45,'[1]5.2 附表1'!$E$29:$BC$60,T$2+1,) -> 0.064125 | U45: 0 | V45: 0 | W45: 0 | X45: 0 | Y45: 0 | Z45: 0 | AA45: 0 | AB45: 0 | AC45: 0 | AD45: 0 | AE45: 0 | AF45: 0 | AG45: 0 | AH45: 0 | AI45: 0 | AJ45: 0
C46: NES | D46: Alloys | E46: =C46&D46 -> NESAlloys | F46: =VLOOKUP($E46,'[1]5.2 附表1'!$E$29:$BC$60,F$2+1,) -> 0.2052 | G46: =VLOOKUP($E46,'[1]5.2 附表1'!$E$29:$BC$60,G$2+1,) -> 0.1884 | H46: =VLOOKUP($E46,'[1]5.2 附表1'!$E$29:$BC$60,H$2+1,) -> 0.1884 | I46: =VLOOKUP($E46,'[1]5.2 附表1'!$E$29:$BC$60,I$2+1,) -> 0.1884 | J46: =VLOOKUP($E46,'[1]5.2 附表1'!$E$29:$BC$60,J$2+1,) -> 0.1884 | K46: =VLOOKUP($E46,'[1]5.2 附表1'!$E$29:$BC$60,K$2+1,) -> 0.1884 | L46: =VLOOKUP($E46,'[1]5.2 附表1'!$E$29:$BC$60,L$2+1,) -> 0.1026 | M46: =VLOOKUP($E46,'[1]5.2 附表1'!$E$29:$BC$60,M$2+1,) -> 0.1026 | ... T46: =VLOOKUP($E46,'[1]5.2 附表1'!$E$29:$BC$60,T$2+1,) -> 0.07695 | U46: 0 | V46: 0 | W46: 0 | X46: 0 | Y46: 0 | Z46: 0 | AA46: 0 | AB46: 0 | AC46: 0 | AD46: 0 | AE46: 0 | AF46: 0 | AG46: 0 | AH46: 0 | AI46: 0 | AJ46: 0
...
